<?xml version="1.0" encoding="UTF-8"?>
<!-- Generated by org.testng.reporters.JUnitReportReporter -->
<testsuite hostname="NVHA" name="TestHIS.TestLuongDichVu_13773" tests="8" failures="2" timestamp="5 Dec 2017 09:48:58 GMT" time="344.734" errors="0">
  <testcase name="DichVu_13773_5" time="19.914" classname="TestHIS.TestLuongDichVu_13773"/>
  <testcase name="DichVu_13773_6" time="55.792" classname="TestHIS.TestLuongDichVu_13773">
    <failure type="java.lang.AssertionError" message="Không in thành công giấy khám thêm cho bệnh nhân !">
      <![CDATA[java.lang.AssertionError: Không in thành công giấy khám thêm cho bệnh nhân !
	at org.testng.Assert.fail(Assert.java:94)
	at desktop_Framework.CommonActions.setTestcaseStatus(CommonActions.java:520)
	at TestHIS.TestLuongDichVu_13773.DichVu_13773_6(TestLuongDichVu_13773.java:435)
	at sun.reflect.NativeMethodAccessorImpl.invoke0(Native Method)
	at sun.reflect.NativeMethodAccessorImpl.invoke(Unknown Source)
	at sun.reflect.DelegatingMethodAccessorImpl.invoke(Unknown Source)
	at java.lang.reflect.Method.invoke(Unknown Source)
	at org.testng.internal.MethodInvocationHelper.invokeMethod(MethodInvocationHelper.java:85)
	at org.testng.internal.Invoker.invokeMethod(Invoker.java:639)
	at org.testng.internal.Invoker.invokeTestMethod(Invoker.java:816)
	at org.testng.internal.Invoker.invokeTestMethods(Invoker.java:1124)
	at org.testng.internal.TestMethodWorker.invokeTestMethods(TestMethodWorker.java:125)
	at org.testng.internal.TestMethodWorker.run(TestMethodWorker.java:108)
	at org.testng.TestRunner.privateRun(TestRunner.java:774)
	at org.testng.TestRunner.run(TestRunner.java:624)
	at org.testng.SuiteRunner.runTest(SuiteRunner.java:359)
	at org.testng.SuiteRunner.runSequentially(SuiteRunner.java:354)
	at org.testng.SuiteRunner.privateRun(SuiteRunner.java:312)
	at org.testng.SuiteRunner.run(SuiteRunner.java:261)
	at org.testng.SuiteRunnerWorker.runSuite(SuiteRunnerWorker.java:52)
	at org.testng.SuiteRunnerWorker.run(SuiteRunnerWorker.java:86)
	at org.testng.TestNG.runSuitesSequentially(TestNG.java:1215)
	at org.testng.TestNG.runSuitesLocally(TestNG.java:1140)
	at org.testng.TestNG.run(TestNG.java:1048)
	at org.testng.remote.AbstractRemoteTestNG.run(AbstractRemoteTestNG.java:114)
	at org.testng.remote.RemoteTestNG.initAndRun(RemoteTestNG.java:251)
	at org.testng.remote.RemoteTestNG.main(RemoteTestNG.java:77)
]]>
    </failure>
  </testcase> <!-- DichVu_13773_6 -->
  <testcase name="DichVu_13773_3" time="32.383" classname="TestHIS.TestLuongDichVu_13773"/>
  <testcase name="DichVu_13773_8" time="46.390" classname="TestHIS.TestLuongDichVu_13773"/>
  <testcase name="DichVu_13773_7" time="7.137" classname="TestHIS.TestLuongDichVu_13773"/>
  <testcase name="DichVu_13773_4" time="28.988" classname="TestHIS.TestLuongDichVu_13773"/>
  <testcase name="DichVu_13773_1" time="61.900" classname="TestHIS.TestLuongDichVu_13773">
    <failure type="java.lang.AssertionError" message="Tiếp nhận Bệnh nhân không thành công !">
      <![CDATA[java.lang.AssertionError: Tiếp nhận Bệnh nhân không thành công !
	at org.testng.Assert.fail(Assert.java:94)
	at desktop_Framework.CommonActions.setTestcaseStatus(CommonActions.java:520)
	at TestHIS.TestLuongDichVu_13773.DichVu_13773_1(TestLuongDichVu_13773.java:144)
	at sun.reflect.NativeMethodAccessorImpl.invoke0(Native Method)
	at sun.reflect.NativeMethodAccessorImpl.invoke(Unknown Source)
	at sun.reflect.DelegatingMethodAccessorImpl.invoke(Unknown Source)
	at java.lang.reflect.Method.invoke(Unknown Source)
	at org.testng.internal.MethodInvocationHelper.invokeMethod(MethodInvocationHelper.java:85)
	at org.testng.internal.Invoker.invokeMethod(Invoker.java:639)
	at org.testng.internal.Invoker.invokeTestMethod(Invoker.java:816)
	at org.testng.internal.Invoker.invokeTestMethods(Invoker.java:1124)
	at org.testng.internal.TestMethodWorker.invokeTestMethods(TestMethodWorker.java:125)
	at org.testng.internal.TestMethodWorker.run(TestMethodWorker.java:108)
	at org.testng.TestRunner.privateRun(TestRunner.java:774)
	at org.testng.TestRunner.run(TestRunner.java:624)
	at org.testng.SuiteRunner.runTest(SuiteRunner.java:359)
	at org.testng.SuiteRunner.runSequentially(SuiteRunner.java:354)
	at org.testng.SuiteRunner.privateRun(SuiteRunner.java:312)
	at org.testng.SuiteRunner.run(SuiteRunner.java:261)
	at org.testng.SuiteRunnerWorker.runSuite(SuiteRunnerWorker.java:52)
	at org.testng.SuiteRunnerWorker.run(SuiteRunnerWorker.java:86)
	at org.testng.TestNG.runSuitesSequentially(TestNG.java:1215)
	at org.testng.TestNG.runSuitesLocally(TestNG.java:1140)
	at org.testng.TestNG.run(TestNG.java:1048)
	at org.testng.remote.AbstractRemoteTestNG.run(AbstractRemoteTestNG.java:114)
	at org.testng.remote.RemoteTestNG.initAndRun(RemoteTestNG.java:251)
	at org.testng.remote.RemoteTestNG.main(RemoteTestNG.java:77)
]]>
    </failure>
  </testcase> <!-- DichVu_13773_1 -->
  <testcase name="DichVu_13773_2" time="92.230" classname="TestHIS.TestLuongDichVu_13773"/>
</testsuite> <!-- TestHIS.TestLuongDichVu_13773 -->
