<?xml version="1.0" encoding="UTF-8"?>
<!-- Generated by org.testng.reporters.JUnitReportReporter -->
<testsuite hostname="NVHA" name="TestHIS.TestLuongDichVu_13766" tests="8" failures="3" timestamp="8 Dec 2017 02:03:27 GMT" time="351.601" errors="0">
  <testcase name="DichVu_13766_1" time="63.201" classname="TestHIS.TestLuongDichVu_13766">
    <failure type="java.lang.AssertionError" message="Tiếp nhận Bệnh nhân không thành công !">
      <![CDATA[java.lang.AssertionError: Tiếp nhận Bệnh nhân không thành công !
	at org.testng.Assert.fail(Assert.java:94)
	at desktop_Framework.CommonActions.setTestcaseStatus(CommonActions.java:523)
	at TestHIS.TestLuongDichVu_13766.DichVu_13766_1(TestLuongDichVu_13766.java:146)
	at sun.reflect.NativeMethodAccessorImpl.invoke0(Native Method)
	at sun.reflect.NativeMethodAccessorImpl.invoke(Unknown Source)
	at sun.reflect.DelegatingMethodAccessorImpl.invoke(Unknown Source)
	at java.lang.reflect.Method.invoke(Unknown Source)
	at org.testng.internal.MethodInvocationHelper.invokeMethod(MethodInvocationHelper.java:85)
	at org.testng.internal.Invoker.invokeMethod(Invoker.java:639)
	at org.testng.internal.Invoker.invokeTestMethod(Invoker.java:816)
	at org.testng.internal.Invoker.invokeTestMethods(Invoker.java:1124)
	at org.testng.internal.TestMethodWorker.invokeTestMethods(TestMethodWorker.java:125)
	at org.testng.internal.TestMethodWorker.run(TestMethodWorker.java:108)
	at org.testng.TestRunner.privateRun(TestRunner.java:774)
	at org.testng.TestRunner.run(TestRunner.java:624)
	at org.testng.SuiteRunner.runTest(SuiteRunner.java:359)
	at org.testng.SuiteRunner.runSequentially(SuiteRunner.java:354)
	at org.testng.SuiteRunner.privateRun(SuiteRunner.java:312)
	at org.testng.SuiteRunner.run(SuiteRunner.java:261)
	at org.testng.SuiteRunnerWorker.runSuite(SuiteRunnerWorker.java:52)
	at org.testng.SuiteRunnerWorker.run(SuiteRunnerWorker.java:86)
	at org.testng.TestNG.runSuitesSequentially(TestNG.java:1215)
	at org.testng.TestNG.runSuitesLocally(TestNG.java:1140)
	at org.testng.TestNG.run(TestNG.java:1048)
	at org.testng.remote.AbstractRemoteTestNG.run(AbstractRemoteTestNG.java:114)
	at org.testng.remote.RemoteTestNG.initAndRun(RemoteTestNG.java:251)
	at org.testng.remote.RemoteTestNG.main(RemoteTestNG.java:77)
]]>
    </failure>
  </testcase> <!-- DichVu_13766_1 -->
  <testcase name="DichVu_13766_6" time="63.782" classname="TestHIS.TestLuongDichVu_13766">
    <failure type="java.lang.AssertionError" message="Không in thành công giấy nghỉ ốm cho bệnh nhân !">
      <![CDATA[java.lang.AssertionError: Không in thành công giấy nghỉ ốm cho bệnh nhân !
	at org.testng.Assert.fail(Assert.java:94)
	at desktop_Framework.CommonActions.setTestcaseStatus(CommonActions.java:523)
	at TestHIS.TestLuongDichVu_13766.DichVu_13766_6(TestLuongDichVu_13766.java:432)
	at sun.reflect.NativeMethodAccessorImpl.invoke0(Native Method)
	at sun.reflect.NativeMethodAccessorImpl.invoke(Unknown Source)
	at sun.reflect.DelegatingMethodAccessorImpl.invoke(Unknown Source)
	at java.lang.reflect.Method.invoke(Unknown Source)
	at org.testng.internal.MethodInvocationHelper.invokeMethod(MethodInvocationHelper.java:85)
	at org.testng.internal.Invoker.invokeMethod(Invoker.java:639)
	at org.testng.internal.Invoker.invokeTestMethod(Invoker.java:816)
	at org.testng.internal.Invoker.invokeTestMethods(Invoker.java:1124)
	at org.testng.internal.TestMethodWorker.invokeTestMethods(TestMethodWorker.java:125)
	at org.testng.internal.TestMethodWorker.run(TestMethodWorker.java:108)
	at org.testng.TestRunner.privateRun(TestRunner.java:774)
	at org.testng.TestRunner.run(TestRunner.java:624)
	at org.testng.SuiteRunner.runTest(SuiteRunner.java:359)
	at org.testng.SuiteRunner.runSequentially(SuiteRunner.java:354)
	at org.testng.SuiteRunner.privateRun(SuiteRunner.java:312)
	at org.testng.SuiteRunner.run(SuiteRunner.java:261)
	at org.testng.SuiteRunnerWorker.runSuite(SuiteRunnerWorker.java:52)
	at org.testng.SuiteRunnerWorker.run(SuiteRunnerWorker.java:86)
	at org.testng.TestNG.runSuitesSequentially(TestNG.java:1215)
	at org.testng.TestNG.runSuitesLocally(TestNG.java:1140)
	at org.testng.TestNG.run(TestNG.java:1048)
	at org.testng.remote.AbstractRemoteTestNG.run(AbstractRemoteTestNG.java:114)
	at org.testng.remote.RemoteTestNG.initAndRun(RemoteTestNG.java:251)
	at org.testng.remote.RemoteTestNG.main(RemoteTestNG.java:77)
]]>
    </failure>
  </testcase> <!-- DichVu_13766_6 -->
  <testcase name="DichVu_13766_4" time="28.990" classname="TestHIS.TestLuongDichVu_13766"/>
  <testcase name="DichVu_13766_7" time="7.608" classname="TestHIS.TestLuongDichVu_13766"/>
  <testcase name="DichVu_13766_5" time="19.904" classname="TestHIS.TestLuongDichVu_13766"/>
  <testcase name="DichVu_13766_8" time="42.977" classname="TestHIS.TestLuongDichVu_13766">
    <failure type="java.lang.AssertionError" message="Không tìm thấy đủ thông tin người cần thanh toán viện phí ,thiếu thông tin toa thuốc ! ">
      <![CDATA[java.lang.AssertionError: Không tìm thấy đủ thông tin người cần thanh toán viện phí ,thiếu thông tin toa thuốc ! 
	at org.testng.Assert.fail(Assert.java:94)
	at desktop_Framework.CommonActions.setTestcaseStatus(CommonActions.java:523)
	at TestHIS.TestLuongDichVu_13766.DichVu_13766_8(TestLuongDichVu_13766.java:531)
	at sun.reflect.NativeMethodAccessorImpl.invoke0(Native Method)
	at sun.reflect.NativeMethodAccessorImpl.invoke(Unknown Source)
	at sun.reflect.DelegatingMethodAccessorImpl.invoke(Unknown Source)
	at java.lang.reflect.Method.invoke(Unknown Source)
	at org.testng.internal.MethodInvocationHelper.invokeMethod(MethodInvocationHelper.java:85)
	at org.testng.internal.Invoker.invokeMethod(Invoker.java:639)
	at org.testng.internal.Invoker.invokeTestMethod(Invoker.java:816)
	at org.testng.internal.Invoker.invokeTestMethods(Invoker.java:1124)
	at org.testng.internal.TestMethodWorker.invokeTestMethods(TestMethodWorker.java:125)
	at org.testng.internal.TestMethodWorker.run(TestMethodWorker.java:108)
	at org.testng.TestRunner.privateRun(TestRunner.java:774)
	at org.testng.TestRunner.run(TestRunner.java:624)
	at org.testng.SuiteRunner.runTest(SuiteRunner.java:359)
	at org.testng.SuiteRunner.runSequentially(SuiteRunner.java:354)
	at org.testng.SuiteRunner.privateRun(SuiteRunner.java:312)
	at org.testng.SuiteRunner.run(SuiteRunner.java:261)
	at org.testng.SuiteRunnerWorker.runSuite(SuiteRunnerWorker.java:52)
	at org.testng.SuiteRunnerWorker.run(SuiteRunnerWorker.java:86)
	at org.testng.TestNG.runSuitesSequentially(TestNG.java:1215)
	at org.testng.TestNG.runSuitesLocally(TestNG.java:1140)
	at org.testng.TestNG.run(TestNG.java:1048)
	at org.testng.remote.AbstractRemoteTestNG.run(AbstractRemoteTestNG.java:114)
	at org.testng.remote.RemoteTestNG.initAndRun(RemoteTestNG.java:251)
	at org.testng.remote.RemoteTestNG.main(RemoteTestNG.java:77)
]]>
    </failure>
  </testcase> <!-- DichVu_13766_8 -->
  <testcase name="DichVu_13766_3" time="32.681" classname="TestHIS.TestLuongDichVu_13766"/>
  <testcase name="DichVu_13766_2" time="92.458" classname="TestHIS.TestLuongDichVu_13766"/>
</testsuite> <!-- TestHIS.TestLuongDichVu_13766 -->
