<?xml version="1.0" encoding="UTF-8"?>
<!-- Generated by org.testng.reporters.JUnitReportReporter -->
<testsuite hostname="NVHA" name="TestHIS.TestLuongTiepNhanBNDichVu_ThuTienSau2" tests="5" failures="3" timestamp="27 Nov 2017 07:55:20 GMT" time="178.016" errors="0">
  <testcase name="TestLuongTiepNhanBenhNhanDichVu_ThuTienSau_2" time="22.339" classname="TestHIS.TestLuongTiepNhanBNDichVu_ThuTienSau2"/>
  <testcase name="TestLuongTiepNhanBenhNhanDichVu_ThuTienSau_4" time="23.908" classname="TestHIS.TestLuongTiepNhanBNDichVu_ThuTienSau2">
    <failure type="java.lang.AssertionError" message="Lưu Chỉ số sinh tồn gặp sự cố !">
      <![CDATA[java.lang.AssertionError: Lưu Chỉ số sinh tồn gặp sự cố !
	at org.testng.Assert.fail(Assert.java:94)
	at desktop_Framework.CommonActions.setTestcaseStatus(CommonActions.java:542)
	at TestHIS.TestLuongTiepNhanBNDichVu_ThuTienSau2.TestLuongTiepNhanBenhNhanDichVu_ThuTienSau_4(TestLuongTiepNhanBNDichVu_ThuTienSau2.java:229)
	at sun.reflect.NativeMethodAccessorImpl.invoke0(Native Method)
	at sun.reflect.NativeMethodAccessorImpl.invoke(Unknown Source)
	at sun.reflect.DelegatingMethodAccessorImpl.invoke(Unknown Source)
	at java.lang.reflect.Method.invoke(Unknown Source)
	at org.testng.internal.MethodInvocationHelper.invokeMethod(MethodInvocationHelper.java:85)
	at org.testng.internal.Invoker.invokeMethod(Invoker.java:639)
	at org.testng.internal.Invoker.invokeTestMethod(Invoker.java:816)
	at org.testng.internal.Invoker.invokeTestMethods(Invoker.java:1124)
	at org.testng.internal.TestMethodWorker.invokeTestMethods(TestMethodWorker.java:125)
	at org.testng.internal.TestMethodWorker.run(TestMethodWorker.java:108)
	at org.testng.TestRunner.privateRun(TestRunner.java:774)
	at org.testng.TestRunner.run(TestRunner.java:624)
	at org.testng.SuiteRunner.runTest(SuiteRunner.java:359)
	at org.testng.SuiteRunner.runSequentially(SuiteRunner.java:354)
	at org.testng.SuiteRunner.privateRun(SuiteRunner.java:312)
	at org.testng.SuiteRunner.run(SuiteRunner.java:261)
	at org.testng.SuiteRunnerWorker.runSuite(SuiteRunnerWorker.java:52)
	at org.testng.SuiteRunnerWorker.run(SuiteRunnerWorker.java:86)
	at org.testng.TestNG.runSuitesSequentially(TestNG.java:1215)
	at org.testng.TestNG.runSuitesLocally(TestNG.java:1140)
	at org.testng.TestNG.run(TestNG.java:1048)
	at org.testng.remote.AbstractRemoteTestNG.run(AbstractRemoteTestNG.java:114)
	at org.testng.remote.RemoteTestNG.initAndRun(RemoteTestNG.java:251)
	at org.testng.remote.RemoteTestNG.main(RemoteTestNG.java:77)
]]>
    </failure>
  </testcase> <!-- TestLuongTiepNhanBenhNhanDichVu_ThuTienSau_4 -->
  <testcase name="TestLuongTiepNhanBenhNhanDichVu_ThuTienSau_1" time="62.241" classname="TestHIS.TestLuongTiepNhanBNDichVu_ThuTienSau2">
    <failure type="java.lang.AssertionError" message="Tiếp nhận Bệnh nhân không thành công !">
      <![CDATA[java.lang.AssertionError: Tiếp nhận Bệnh nhân không thành công !
	at org.testng.Assert.fail(Assert.java:94)
	at desktop_Framework.CommonActions.setTestcaseStatus(CommonActions.java:542)
	at TestHIS.TestLuongTiepNhanBNDichVu_ThuTienSau2.TestLuongTiepNhanBenhNhanDichVu_ThuTienSau_1(TestLuongTiepNhanBNDichVu_ThuTienSau2.java:141)
	at sun.reflect.NativeMethodAccessorImpl.invoke0(Native Method)
	at sun.reflect.NativeMethodAccessorImpl.invoke(Unknown Source)
	at sun.reflect.DelegatingMethodAccessorImpl.invoke(Unknown Source)
	at java.lang.reflect.Method.invoke(Unknown Source)
	at org.testng.internal.MethodInvocationHelper.invokeMethod(MethodInvocationHelper.java:85)
	at org.testng.internal.Invoker.invokeMethod(Invoker.java:639)
	at org.testng.internal.Invoker.invokeTestMethod(Invoker.java:816)
	at org.testng.internal.Invoker.invokeTestMethods(Invoker.java:1124)
	at org.testng.internal.TestMethodWorker.invokeTestMethods(TestMethodWorker.java:125)
	at org.testng.internal.TestMethodWorker.run(TestMethodWorker.java:108)
	at org.testng.TestRunner.privateRun(TestRunner.java:774)
	at org.testng.TestRunner.run(TestRunner.java:624)
	at org.testng.SuiteRunner.runTest(SuiteRunner.java:359)
	at org.testng.SuiteRunner.runSequentially(SuiteRunner.java:354)
	at org.testng.SuiteRunner.privateRun(SuiteRunner.java:312)
	at org.testng.SuiteRunner.run(SuiteRunner.java:261)
	at org.testng.SuiteRunnerWorker.runSuite(SuiteRunnerWorker.java:52)
	at org.testng.SuiteRunnerWorker.run(SuiteRunnerWorker.java:86)
	at org.testng.TestNG.runSuitesSequentially(TestNG.java:1215)
	at org.testng.TestNG.runSuitesLocally(TestNG.java:1140)
	at org.testng.TestNG.run(TestNG.java:1048)
	at org.testng.remote.AbstractRemoteTestNG.run(AbstractRemoteTestNG.java:114)
	at org.testng.remote.RemoteTestNG.initAndRun(RemoteTestNG.java:251)
	at org.testng.remote.RemoteTestNG.main(RemoteTestNG.java:77)
]]>
    </failure>
  </testcase> <!-- TestLuongTiepNhanBenhNhanDichVu_ThuTienSau_1 -->
  <testcase name="TestLuongTiepNhanBenhNhanDichVu_ThuTienSau_5" time="11.672" classname="TestHIS.TestLuongTiepNhanBNDichVu_ThuTienSau2">
    <failure type="java.lang.AssertionError" message="Không thể lưu kết quả khám bệnh , gặp sự cố !">
      <![CDATA[java.lang.AssertionError: Không thể lưu kết quả khám bệnh , gặp sự cố !
	at org.testng.Assert.fail(Assert.java:94)
	at desktop_Framework.CommonActions.setTestcaseStatus(CommonActions.java:542)
	at TestHIS.TestLuongTiepNhanBNDichVu_ThuTienSau2.TestLuongTiepNhanBenhNhanDichVu_ThuTienSau_5(TestLuongTiepNhanBNDichVu_ThuTienSau2.java:248)
	at sun.reflect.NativeMethodAccessorImpl.invoke0(Native Method)
	at sun.reflect.NativeMethodAccessorImpl.invoke(Unknown Source)
	at sun.reflect.DelegatingMethodAccessorImpl.invoke(Unknown Source)
	at java.lang.reflect.Method.invoke(Unknown Source)
	at org.testng.internal.MethodInvocationHelper.invokeMethod(MethodInvocationHelper.java:85)
	at org.testng.internal.Invoker.invokeMethod(Invoker.java:639)
	at org.testng.internal.Invoker.invokeTestMethod(Invoker.java:816)
	at org.testng.internal.Invoker.invokeTestMethods(Invoker.java:1124)
	at org.testng.internal.TestMethodWorker.invokeTestMethods(TestMethodWorker.java:125)
	at org.testng.internal.TestMethodWorker.run(TestMethodWorker.java:108)
	at org.testng.TestRunner.privateRun(TestRunner.java:774)
	at org.testng.TestRunner.run(TestRunner.java:624)
	at org.testng.SuiteRunner.runTest(SuiteRunner.java:359)
	at org.testng.SuiteRunner.runSequentially(SuiteRunner.java:354)
	at org.testng.SuiteRunner.privateRun(SuiteRunner.java:312)
	at org.testng.SuiteRunner.run(SuiteRunner.java:261)
	at org.testng.SuiteRunnerWorker.runSuite(SuiteRunnerWorker.java:52)
	at org.testng.SuiteRunnerWorker.run(SuiteRunnerWorker.java:86)
	at org.testng.TestNG.runSuitesSequentially(TestNG.java:1215)
	at org.testng.TestNG.runSuitesLocally(TestNG.java:1140)
	at org.testng.TestNG.run(TestNG.java:1048)
	at org.testng.remote.AbstractRemoteTestNG.run(AbstractRemoteTestNG.java:114)
	at org.testng.remote.RemoteTestNG.initAndRun(RemoteTestNG.java:251)
	at org.testng.remote.RemoteTestNG.main(RemoteTestNG.java:77)
]]>
    </failure>
  </testcase> <!-- TestLuongTiepNhanBenhNhanDichVu_ThuTienSau_5 -->
  <testcase name="TestLuongTiepNhanBenhNhanDichVu_ThuTienSau_3" time="57.856" classname="TestHIS.TestLuongTiepNhanBNDichVu_ThuTienSau2"/>
</testsuite> <!-- TestHIS.TestLuongTiepNhanBNDichVu_ThuTienSau2 -->
