<?xml version="1.0" encoding="UTF-8"?>
<!-- Generated by org.testng.reporters.JUnitReportReporter -->
<testsuite hostname="NVHA" name="TestHIS.TestLuongDichVu_13793" tests="7" failures="1" timestamp="4 Dec 2017 09:49:50 GMT" time="307.531" errors="0">
  <testcase name="DichVu_13793_7" time="42.935" classname="TestHIS.TestLuongDichVu_13793"/>
  <testcase name="DichVu_13793_1" time="61.892" classname="TestHIS.TestLuongDichVu_13793">
    <failure type="java.lang.AssertionError" message="Tiếp nhận Bệnh nhân không thành công !">
      <![CDATA[java.lang.AssertionError: Tiếp nhận Bệnh nhân không thành công !
	at org.testng.Assert.fail(Assert.java:94)
	at desktop_Framework.CommonActions.setTestcaseStatus(CommonActions.java:520)
	at TestHIS.TestLuongDichVu_13793.DichVu_13793_1(TestLuongDichVu_13793.java:144)
	at sun.reflect.NativeMethodAccessorImpl.invoke0(Native Method)
	at sun.reflect.NativeMethodAccessorImpl.invoke(Unknown Source)
	at sun.reflect.DelegatingMethodAccessorImpl.invoke(Unknown Source)
	at java.lang.reflect.Method.invoke(Unknown Source)
	at org.testng.internal.MethodInvocationHelper.invokeMethod(MethodInvocationHelper.java:85)
	at org.testng.internal.Invoker.invokeMethod(Invoker.java:639)
	at org.testng.internal.Invoker.invokeTestMethod(Invoker.java:816)
	at org.testng.internal.Invoker.invokeTestMethods(Invoker.java:1124)
	at org.testng.internal.TestMethodWorker.invokeTestMethods(TestMethodWorker.java:125)
	at org.testng.internal.TestMethodWorker.run(TestMethodWorker.java:108)
	at org.testng.TestRunner.privateRun(TestRunner.java:774)
	at org.testng.TestRunner.run(TestRunner.java:624)
	at org.testng.SuiteRunner.runTest(SuiteRunner.java:359)
	at org.testng.SuiteRunner.runSequentially(SuiteRunner.java:354)
	at org.testng.SuiteRunner.privateRun(SuiteRunner.java:312)
	at org.testng.SuiteRunner.run(SuiteRunner.java:261)
	at org.testng.SuiteRunnerWorker.runSuite(SuiteRunnerWorker.java:52)
	at org.testng.SuiteRunnerWorker.run(SuiteRunnerWorker.java:86)
	at org.testng.TestNG.runSuitesSequentially(TestNG.java:1215)
	at org.testng.TestNG.runSuitesLocally(TestNG.java:1140)
	at org.testng.TestNG.run(TestNG.java:1048)
	at org.testng.remote.AbstractRemoteTestNG.run(AbstractRemoteTestNG.java:114)
	at org.testng.remote.RemoteTestNG.initAndRun(RemoteTestNG.java:251)
	at org.testng.remote.RemoteTestNG.main(RemoteTestNG.java:77)
]]>
    </failure>
  </testcase> <!-- DichVu_13793_1 -->
  <testcase name="DichVu_13793_4" time="30.191" classname="TestHIS.TestLuongDichVu_13793"/>
  <testcase name="DichVu_13793_5" time="16.123" classname="TestHIS.TestLuongDichVu_13793"/>
  <testcase name="DichVu_13793_2" time="92.489" classname="TestHIS.TestLuongDichVu_13793"/>
  <testcase name="DichVu_13793_6" time="31.836" classname="TestHIS.TestLuongDichVu_13793"/>
  <testcase name="DichVu_13793_3" time="32.065" classname="TestHIS.TestLuongDichVu_13793"/>
</testsuite> <!-- TestHIS.TestLuongDichVu_13793 -->
